/home/longvv/anaconda3/lib/python3.10/site-packages/torch/nn/modules/conv.py:952: UserWarning: Plan failed with a cudnnException: CUDNN_BACKEND_EXECUTION_PLAN_DESCRIPTOR: cudnnFinalize Descriptor Failed cudnn_status: CUDNN_STATUS_NOT_SUPPORTED (Triggered internally at ../aten/src/ATen/native/cudnn/Conv_v8.cpp:919.)
  return F.conv_transpose2d(
/home/longvv/anaconda3/lib/python3.10/site-packages/torch/autograd/graph.py:744: UserWarning: Plan failed with a cudnnException: CUDNN_BACKEND_EXECUTION_PLAN_DESCRIPTOR: cudnnFinalize Descriptor Failed cudnn_status: CUDNN_STATUS_NOT_SUPPORTED (Triggered internally at ../aten/src/ATen/native/cudnn/Conv_v8.cpp:919.)
  return Variable._execution_engine.run_backward(  # Calls into the C++ engine to run the backward pass
Epoch 0 | step 000 Loss: 1.046587347984314
Epoch 0 | step 030 Loss: 0.11298353970050812
Epoch 0 | step 060 Loss: 0.05179711431264877
Epoch 0 | step 090 Loss: 0.05031534656882286
/home/longvv/anaconda3/lib/python3.10/site-packages/torch/nn/modules/conv.py:456: UserWarning: Plan failed with a cudnnException: CUDNN_BACKEND_EXECUTION_PLAN_DESCRIPTOR: cudnnFinalize Descriptor Failed cudnn_status: CUDNN_STATUS_NOT_SUPPORTED (Triggered internally at ../aten/src/ATen/native/cudnn/Conv_v8.cpp:919.)
  return F.conv2d(input, weight, bias, self.stride,
Traceback (most recent call last):
  File "/home/longvv/generative_model/diffusion-real/train.py", line 163, in <module>
    sample_plot_image((epoch + 1)//5)
  File "/home/longvv/anaconda3/lib/python3.10/site-packages/torch/utils/_contextlib.py", line 115, in decorate_context
    return func(*args, **kwargs)
  File "/home/longvv/generative_model/diffusion-real/train.py", line 112, in sample_plot_image
    show_images(img_name, img_set, save = True)
  File "/home/longvv/generative_model/diffusion-real/train.py", line 86, in show_images
    img = convert_to_image(img)
NameError: name 'convert_to_image' is not defined
