/home/longvv/anaconda3/lib/python3.10/site-packages/torch/nn/modules/conv.py:952: UserWarning: Plan failed with a cudnnException: CUDNN_BACKEND_EXECUTION_PLAN_DESCRIPTOR: cudnnFinalize Descriptor Failed cudnn_status: CUDNN_STATUS_NOT_SUPPORTED (Triggered internally at ../aten/src/ATen/native/cudnn/Conv_v8.cpp:919.)
  return F.conv_transpose2d(
/home/longvv/anaconda3/lib/python3.10/site-packages/torch/autograd/graph.py:744: UserWarning: Plan failed with a cudnnException: CUDNN_BACKEND_EXECUTION_PLAN_DESCRIPTOR: cudnnFinalize Descriptor Failed cudnn_status: CUDNN_STATUS_NOT_SUPPORTED (Triggered internally at ../aten/src/ATen/native/cudnn/Conv_v8.cpp:919.)
  return Variable._execution_engine.run_backward(  # Calls into the C++ engine to run the backward pass
Epoch 0 | step 000 Loss: 1.029242992401123
Epoch 0 | step 030 Loss: 0.11089136451482773
Epoch 0 | step 060 Loss: 0.06199748441576958
Epoch 0 | step 090 Loss: 0.05395687744021416
/home/longvv/anaconda3/lib/python3.10/site-packages/torch/nn/modules/conv.py:456: UserWarning: Plan failed with a cudnnException: CUDNN_BACKEND_EXECUTION_PLAN_DESCRIPTOR: cudnnFinalize Descriptor Failed cudnn_status: CUDNN_STATUS_NOT_SUPPORTED (Triggered internally at ../aten/src/ATen/native/cudnn/Conv_v8.cpp:919.)
  return F.conv2d(input, weight, bias, self.stride,
Traceback (most recent call last):
  File "/home/longvv/generative_model/diffusion-real/train.py", line 162, in <module>
    sample_plot_image((epoch + 1)//5)
  File "/home/longvv/anaconda3/lib/python3.10/site-packages/torch/utils/_contextlib.py", line 115, in decorate_context
    return func(*args, **kwargs)
  File "/home/longvv/generative_model/diffusion-real/train.py", line 111, in sample_plot_image
    show_images(img_name, img_set, save = True)
  File "/home/longvv/generative_model/diffusion-real/train.py", line 87, in show_images
    plt.imshow(img, cmap='gray')
  File "/home/longvv/anaconda3/lib/python3.10/site-packages/matplotlib/pyplot.py", line 2668, in imshow
    __ret = gca().imshow(
  File "/home/longvv/anaconda3/lib/python3.10/site-packages/matplotlib/__init__.py", line 1442, in inner
    return func(ax, *map(sanitize_sequence, args), **kwargs)
  File "/home/longvv/anaconda3/lib/python3.10/site-packages/matplotlib/axes/_axes.py", line 5665, in imshow
    im.set_data(X)
  File "/home/longvv/anaconda3/lib/python3.10/site-packages/matplotlib/image.py", line 710, in set_data
    raise TypeError("Invalid shape {} for image data"
TypeError: Invalid shape (1, 32, 32) for image data
